Workbook

Sheet Rencana Proyek
A1: RENCANA PROYEK SMART KTM
A2: Teks biru = isian, teks hijau = diambil otomatis dari sheet lain, sel kuning = asumsi yang perlu dicek.
A4: 1. Ringkasan Proyek
B5: Nama Proyek | C5: Smart KTM - AI Agent dan Blockchain pada KTM
B6: Kampus / Kelas | C6: Universitas Pamulang - Kelas 07TPLP003 - Kelompok 11
B7: Project Manager | C7: Rahmat Eka Satria
B8: Tanggal Mulai | C8: 46321
B9: Target Selesai | C9: =MAX(Jadwal!G7:G31) -> 46342
B10: Lama Proyek (hari) | C10: =C9-C8+1 -> 22
B11: Total Anggaran (Rp) | C11: =Anggaran!F39 -> 38553075
B12: Progres Proyek | C12: =IFERROR((Jadwal!F7*Jadwal!H7+Jadwal!F12*Jadwal!H12+Jadwal!F18*Jadwal!H18+Jadwal!F22*Jadwal!H22+Jadwal!F27*Jadwal!H27)/(Jadwal!F7+Jadwal!F12+Jadwal!F18+Jadwal!F22+Jadwal!F27),0) -> 0.24285714
B13: Kondisi Saat Ini | C13: =IF(C12>=1,"Selesai",IF(COUNTIF(Jadwal!I7:I31,"Terlambat")>0,"Ada Keterlambatan",IF(C12>0,"Berjalan","Belum Mulai"))) -> Berjalan
B14: Jumlah Pekerjaan | C14: =COUNTIF(Jadwal!A7:A31,"T*") -> 20
B15: Pekerjaan Selesai | C15: =COUNTIFS(Jadwal!A7:A31,"T*",Jadwal!I7:I31,"Selesai") -> 14
B16: Pekerjaan Terlambat | C16: =COUNTIFS(Jadwal!A7:A31,"T*",Jadwal!I7:I31,"Terlambat") -> 0
B17: Tautan | C17: https://ktm.rahmateka.my.id · github.com/rhmatzeka/smart-ktm · github.com/users/rhmatzeka/projects/3
A19: 2. Sasaran
A20: 1 | B20: Menjadikan KTM fisik (MIFARE Classic, kartu parkir yang sama) kunci masuk aplikasi akademik lewat NFC, tanpa menulis apa pun ke kartu.
A21: 2 | B21: Mencatat presensi kelas anti titip absen (tap KTM + foto mahasiswa di HP dosen) dengan bukti hash di blockchain Ethereum Sepolia yang bisa diverifikasi publik.
A22: 3 | B22: Menyediakan AI agent akademik yang menjawab dan bertindak (catat tugas, pengingat) dari data jadwal & presensi MyUnpam milik mahasiswa sendiri.
A23: 4 | B23: Menerbitkan sertifikat acara on-chain lewat tap KTM dan melindungi KTM hilang (blokir kartu, pesan untuk penemu).
A25: 3. Lingkup Pekerjaan & Hasil
A26: No | B26: Hasil | C26: Isi | D26: Dianggap Berhasil Bila | E26: Prioritas | F26: Penanggung Jawab
A27: 1 | B27: Tap KTM & akun | C27: Masuk dengan tap KTM (Web NFC & NFC native), daftar KTM, HP tepercaya, ganti PIN | D27: UID terbaca; tap KTM masuk <= 3 detik di HP tepercaya; tanpa jalur tulis ke kartu | E27: Tinggi | F27: Backend & Blockchain
A28: 2 | B28: Beranda & jadwal (MyUnpam) | C28: Sinkron jadwal, presensi per pertemuan & foto lewat bookmark; beranda sesuai waktu; jadwal seminggu | D28: Data sama dengan MyUnpam; pertemuan terlewat tampil | E28: Tinggi | F28: Frontend & Mobile
A29: 3 | B29: Presensi on-chain | C29: Mesin absen di HP dosen, foto mahasiswa, hash ke kontrak PresensiKTM, halaman cek bukti | D29: Tercatat di Sepolia & bisa dibuka di Etherscan; tap ganda ditolak | E29: Tinggi | F29: Backend & Blockchain
A30: 4 | B30: AI Agent (Asisten KTM) | C30: Tanya jawab dari data sendiri, catat tugas, pengingat, ringkasan beranda | D30: Jawaban sesuai data; aksi benar-benar tersimpan; mode offline bila AI mati | E30: Tinggi | F30: AI Engineer
A31: 5 | B31: Sertifikat, KTM hilang & kartu nama | C31: Sertifikat acara on-chain, blokir KTM hilang, kartu nama digital | D31: Sertifikat terverifikasi di Etherscan; KTM hilang ditolak di semua jalur | E31: Sedang | F31: Backend & Blockchain
A32: 6 | B32: Aplikasi Android | C32: Capacitor + plugin NFC native: tempel KTM membuka aplikasi; APK dari GitHub Actions | D32: APK terpasang; aplikasi terbuka saat KTM ditempel | E32: Sedang | F32: Frontend & Mobile
A34: Tidak termasuk tugas ini (rencana pengembangan): menulis data ke MyUnpam/SIAKAD, notifikasi WhatsApp, sinkron tugas Mentari, rilis Play Store, aplikasi iOS native, kartu DESFire.
A36: 4. Titik Capaian
A37: No | B37: Titik Capaian | C37: Bukti Tercapai | D37: Target | E37: Status
A38: 1 | B38: Kickoff & uji kelayakan NFC | C38: UID KTM terbaca, judul disetujui | D38: =Jadwal!G10 -> 46322 | E38: =Jadwal!I10 -> Selesai
A39: 2 | B39: Backend, kontrak & AI selesai | C39: API, PresensiKTM, AI agent berfungsi | D39: =Jadwal!G17 -> 46322 | E39: =Jadwal!I17 -> Selesai
A40: 3 | B40: Frontend & aplikasi Android selesai | C40: Web + APK berjalan dengan data MyUnpam | D40: =Jadwal!G21 -> 46322 | E40: =Jadwal!I21 -> Selesai
A41: 4 | B41: Presentasi & demo | C41: Demo tap KTM, presensi on-chain, AI | D41: =Jadwal!G24 -> 46323 | E41: =Jadwal!I24 -> Belum Mulai
A42: 5 | B42: UAT selesai | C42: Berita acara UAT bersama dosen | D42: =Jadwal!G26 -> 46331 | E42: =Jadwal!I26 -> Belum Mulai
A43: 6 | B43: Go-live & serah terima | C43: APK final, laporan, repo publik | D43: =Jadwal!G31 -> 46342 | E43: =Jadwal!I31 -> Belum Mulai
A45: 5. Tim Kelompok 11
A46: No | B46: Peran | C46: Nama | D46: Tugas Utama | E46: Porsi Waktu
...

Sheet Anggaran
A1: ANGGARAN BIAYA PROYEK (RAB)
A2: ='Rencana Proyek'!C5 -> Smart KTM - AI Agent dan Blockchain pada KTM
A3: Mata uang: Rupiah (Rp). Harga satuan adalah ASUMSI - sesuaikan dengan penawaran/standar biaya institusi. Kolom Keterangan menyebut biaya yang sebenarnya dipakai di prototipe.
A5: No | B5: Komponen Biaya | C5: Satuan | D5: Jumlah Unit | E5: Harga per Unit (Rp) | F5: Total (Rp) | G5: Catatan
A6: A | B6: Tenaga Kerja
A7: 1 | B7: Project Manager | C7: bulan | D7: 1.5 | E7: 3000000 | F7: =D7*E7 -> 4500000 | G7: Koordinasi, demo, UAT, laporan
A8: 2 | B8: Backend & Blockchain Developer (Rust, Solidity) | C8: bulan | D8: 1.5 | E8: 5000000 | F8: =D8*E8 -> 7500000
A9: 3 | B9: Frontend & Mobile Developer (Astro, Android) | C9: bulan | D9: 1.5 | E9: 4500000 | F9: =D9*E9 -> 6750000
A10: 4 | B10: AI Engineer | C10: bulan | D10: 1 | E10: 4500000 | F10: =D10*E10 -> 4500000 | G10: Asisten KTM (function calling)
A11: 5 | B11: QA / Tester | C11: bulan | D11: 1 | E11: 2500000 | F11: =D11*E11 -> 2500000
B12: Subtotal A | F12: =SUM(F7:F11) -> 25750000
A13: B | B13: Perangkat Keras
A14: 1 | B14: HP Android ber-NFC untuk mesin absen dosen | C14: unit | D14: 1 | E14: 2500000 | F14: =D14*E14 -> 2500000 | G14: Prototipe memakai HP anggota
A15: 2 | B15: Kartu NFC cadangan untuk uji (NTAG/MIFARE) | C15: pcs | D15: 20 | E15: 5000 | F15: =D15*E15 -> 100000 | G15: KTM asli tidak pernah ditulis
A16: 3 | B16: Reader NFC USB (opsional, mesin absen di laptop) | C16: unit | D16: 1 | E16: 350000 | F16: =D16*E16 -> 350000
B17: Subtotal B | F17: =SUM(F14:F16) -> 2950000
A18: C | B18: Layanan Online & Lisensi
A19: 1 | B19: VPS / hosting | C19: bulan | D19: 6 | E19: 150000 | F19: =D19*E19 -> 900000 | G19: Prototipe: VPS milik anggota
A20: 2 | B20: Domain (.my.id) | C20: tahun | D20: 1 | E20: 25000 | F20: =D20*E20 -> 25000 | G20: rahmateka.my.id sudah ada
A21: 3 | B21: API AI (Groq / Gemini) | C21: bulan | D21: 2 | E21: 0 | F21: =D21*E21 -> 0 | G21: Tier gratis; siapkan anggaran bila kuota habis
A22: 4 | B22: Gas blockchain (Ethereum Sepolia testnet) | C22: ls | D22: 1 | E22: 0 | F22: =D22*E22 -> 0 | G22: Testnet: SepoliaETH dari faucet
A23: 5 | B23: Akun Google Play Developer | C23: kali | D23: 1 | E23: 400000 | F23: =D23*E23 -> 400000 | G23: Biaya sekali, setara USD 25
A24: 6 | B24: Cloudflare Tunnel & GitHub Actions | C24: bulan | D24: 2 | E24: 0 | F24: =D24*E24 -> 0 | G24: Paket gratis
B25: Subtotal C | F25: =SUM(F19:F24) -> 1325000
A26: D | B26: Uji Coba & Demo
A27: 1 | B27: Konsumsi sesi UAT & demo | C27: sesi | D27: 2 | E27: 300000 | F27: =D27*E27 -> 600000
A28: 2 | B28: Insentif mahasiswa responden uji | C28: orang | D28: 10 | E28: 25000 | F28: =D28*E28 -> 250000
B29: Subtotal D | F29: =SUM(F27:F28) -> 850000
A30: E | B30: Operasional
A31: 1 | B31: Internet / kuota | C31: bulan | D31: 2 | E31: 150000 | F31: =D31*E31 -> 300000
A32: 2 | B32: ATK & cetak laporan | C32: ls | D32: 1 | E32: 200000 | F32: =D32*E32 -> 200000 | G32: Lump sum
A33: 3 | B33: Transportasi & rapat koordinasi | C33: kali | D33: 4 | E33: 50000 | F33: =D33*E33 -> 200000
B34: Subtotal E | F34: =SUM(F31:F33) -> 700000
B36: Jumlah biaya langsung | F36: =F12+F17+F25+F29+F34 -> 31575000
B37: Dana cadangan (%) | E37: 0.1 | F37: =F36*E37 -> 3157500 | G37: Asumsi: 10% untuk biaya tak terduga
B38: PPN (%) | E38: 0.11 | F38: =(F36+F37)*E38 -> 3820575 | G38: Asumsi tarif 11%; isi 0% bila tidak dikenai PPN
B39: TOTAL ANGGARAN | F39: =F36+F37+F38 -> 38553075
B41: Batas anggaran (Rp) | F41: 50000000 | G41: Asumsi contoh - ganti dengan pagu sebenarnya
B42: Sisa / (kekurangan) anggaran (Rp) | F42: =F41-F39 -> 11446925 | G42: =IF(F42<0,"Melebihi batas","Masih dalam batas") -> Masih dalam batas
A44: Ringkasan per Kategori
...

Sheet Jadwal
A1: JADWAL PELAKSANAAN (GANTT)
A2: ='Rencana Proyek'!C5 -> Smart KTM - AI Agent dan Blockchain pada KTM
A3: Warna: | B3: Fase | C3: Tugas | D3: Selesai | E3: Minggu ini
A5: Setelah Tugas = kode pekerjaan yang harus selesai dulu sebelum pekerjaan ini dimulai. Kosong = mulai sejak hari pertama proyek. Teks biru = bisa diubah. | J5: Mg 1 | K5: Mg 2 | L5: Mg 3 | M5: Mg 4 | N5: Mg 5 | O5: Mg 6 | P5: Mg 7 | Q5: Mg 8
A6: Kode | B6: Pekerjaan | C6: Penanggung Jawab | D6: Setelah Tugas | E6: Mulai | F6: Lama (hari) | G6: Selesai | H6: Progres | I6: Status | J6: ='Rencana Proyek'!$C$8 -> 46321 | K6: =J6+7 -> 46328 | L6: =K6+7 -> 46335 | M6: =L6+7 -> 46342 | N6: =M6+7 -> 46349 | O6: =N6+7 -> 46356 | P6: =O6+7 -> 46363 | Q6: =P6+7 -> 46370
A7: F1 | B7: Fase 1 · Inisiasi & Perancangan | E7: =MIN(E8:E11) -> 46321 | F7: =G7-E7+1 -> 2 | G7: =MAX(G8:G11) -> 46322 | H7: =IFERROR(SUMPRODUCT(F8:F11,H8:H11)/SUM(F8:F11),0) -> 1 | I7: =IF(H7>=1,"Selesai",IF(AND(TODAY()>G7,H7<1),"Terlambat",IF(H7>0,"Berjalan","Belum Mulai"))) -> Selesai
A8: T1.1 | B8: Kickoff, ide & ruang lingkup | C8: PM | E8: =IF($D8="",'Rencana Proyek'!$C$8,IFERROR(INDEX($G$7:$G$31,MATCH($D8,$A$7:$A$31,0))+1,'Rencana Proyek'!$C$8)) -> 46321 | F8: 1 | G8: =E8+F8-1 -> 46321 | H8: 1 | I8: =IF(H8>=1,"Selesai",IF(AND(TODAY()>G8,H8<1),"Terlambat",IF(H8>0,"Berjalan","Belum Mulai"))) -> Selesai
A9: T1.2 | B9: Uji kelayakan NFC pada KTM (MIFARE Classic 1K) | C9: Backend & Blockchain | E9: =IF($D9="",'Rencana Proyek'!$C$8,IFERROR(INDEX($G$7:$G$31,MATCH($D9,$A$7:$A$31,0))+1,'Rencana Proyek'!$C$8)) -> 46321 | F9: 1 | G9: =E9+F9-1 -> 46321 | H9: 1 | I9: =IF(H9>=1,"Selesai",IF(AND(TODAY()>G9,H9<1),"Terlambat",IF(H9>0,"Berjalan","Belum Mulai"))) -> Selesai
A10: T1.3 | B10: Riset integrasi MyUnpam & Mentari, penetapan judul | C10: PM | D10: T1.1 | E10: =IF($D10="",'Rencana Proyek'!$C$8,IFERROR(INDEX($G$7:$G$31,MATCH($D10,$A$7:$A$31,0))+1,'Rencana Proyek'!$C$8)) -> 46322 | F10: 1 | G10: =E10+F10-1 -> 46322 | H10: 1 | I10: =IF(H10>=1,"Selesai",IF(AND(TODAY()>G10,H10<1),"Terlambat",IF(H10>0,"Berjalan","Belum Mulai"))) -> Selesai
A11: T1.4 | B11: Mockup & perancangan UI/UX | C11: Frontend & Mobile | D11: T1.1 | E11: =IF($D11="",'Rencana Proyek'!$C$8,IFERROR(INDEX($G$7:$G$31,MATCH($D11,$A$7:$A$31,0))+1,'Rencana Proyek'!$C$8)) -> 46322 | F11: 1 | G11: =E11+F11-1 -> 46322 | H11: 1 | I11: =IF(H11>=1,"Selesai",IF(AND(TODAY()>G11,H11<1),"Terlambat",IF(H11>0,"Berjalan","Belum Mulai"))) -> Selesai
A12: F2 | B12: Fase 2 · Backend & Blockchain | E12: =MIN(E13:E17) -> 46322 | F12: =G12-E12+1 -> 1 | G12: =MAX(G13:G17) -> 46322 | H12: =IFERROR(SUMPRODUCT(F13:F17,H13:H17)/SUM(F13:F17),0) -> 1 | I12: =IF(H12>=1,"Selesai",IF(AND(TODAY()>G12,H12<1),"Terlambat",IF(H12>0,"Berjalan","Belum Mulai"))) -> Selesai
A13: T2.1 | B13: API Rust (axum + SQLite): akun, KTM, jadwal, presensi | C13: Backend & Blockchain | D13: T1.2 | E13: =IF($D13="",'Rencana Proyek'!$C$8,IFERROR(INDEX($G$7:$G$31,MATCH($D13,$A$7:$A$31,0))+1,'Rencana Proyek'!$C$8)) -> 46322 | F13: 1 | G13: =E13+F13-1 -> 46322 | H13: 1 | I13: =IF(H13>=1,"Selesai",IF(AND(TODAY()>G13,H13<1),"Terlambat",IF(H13>0,"Berjalan","Belum Mulai"))) -> Selesai
A14: T2.2 | B14: Smart contract PresensiKTM & SertifikatKTM (Sepolia) | C14: Backend & Blockchain | D14: T1.2 | E14: =IF($D14="",'Rencana Proyek'!$C$8,IFERROR(INDEX($G$7:$G$31,MATCH($D14,$A$7:$A$31,0))+1,'Rencana Proyek'!$C$8)) -> 46322 | F14: 1 | G14: =E14+F14-1 -> 46322 | H14: 1 | I14: =IF(H14>=1,"Selesai",IF(AND(TODAY()>G14,H14<1),"Terlambat",IF(H14>0,"Berjalan","Belum Mulai"))) -> Selesai
A15: T2.3 | B15: AI agent (Groq, function calling) | C15: AI Engineer | D15: T1.2 | E15: =IF($D15="",'Rencana Proyek'!$C$8,IFERROR(INDEX($G$7:$G$31,MATCH($D15,$A$7:$A$31,0))+1,'Rencana Proyek'!$C$8)) -> 46322 | F15: 1 | G15: =E15+F15-1 -> 46322 | H15: 1 | I15: =IF(H15>=1,"Selesai",IF(AND(TODAY()>G15,H15<1),"Terlambat",IF(H15>0,"Berjalan","Belum Mulai"))) -> Selesai
A16: T2.4 | B16: Sinkron MyUnpam: jadwal, presensi per pertemuan, foto | C16: Backend & Blockchain | D16: T1.2 | E16: =IF($D16="",'Rencana Proyek'!$C$8,IFERROR(INDEX($G$7:$G$31,MATCH($D16,$A$7:$A$31,0))+1,'Rencana Proyek'!$C$8)) -> 46322 | F16: 1 | G16: =E16+F16-1 -> 46322 | H16: 1 | I16: =IF(H16>=1,"Selesai",IF(AND(TODAY()>G16,H16<1),"Terlambat",IF(H16>0,"Berjalan","Belum Mulai"))) -> Selesai
A17: T2.5 | B17: Mode KTM hilang & pengamanan akun | C17: Backend & Blockchain | D17: T1.2 | E17: =IF($D17="",'Rencana Proyek'!$C$8,IFERROR(INDEX($G$7:$G$31,MATCH($D17,$A$7:$A$31,0))+1,'Rencana Proyek'!$C$8)) -> 46322 | F17: 1 | G17: =E17+F17-1 -> 46322 | H17: 1 | I17: =IF(H17>=1,"Selesai",IF(AND(TODAY()>G17,H17<1),"Terlambat",IF(H17>0,"Berjalan","Belum Mulai"))) -> Selesai
A18: F3 | B18: Fase 3 · Frontend & Aplikasi Mobile | E18: =MIN(E19:E21) -> 46322 | F18: =G18-E18+1 -> 1 | G18: =MAX(G19:G21) -> 46322 | H18: =IFERROR(SUMPRODUCT(F19:F21,H19:H21)/SUM(F19:F21),0) -> 1 | I18: =IF(H18>=1,"Selesai",IF(AND(TODAY()>G18,H18<1),"Terlambat",IF(H18>0,"Berjalan","Belum Mulai"))) -> Selesai
A19: T3.1 | B19: Web Astro + Web NFC: masuk, beranda, mesin absen | C19: Frontend & Mobile | D19: T1.2 | E19: =IF($D19="",'Rencana Proyek'!$C$8,IFERROR(INDEX($G$7:$G$31,MATCH($D19,$A$7:$A$31,0))+1,'Rencana Proyek'!$C$8)) -> 46322 | F19: 1 | G19: =E19+F19-1 -> 46322 | H19: 1 | I19: =IF(H19>=1,"Selesai",IF(AND(TODAY()>G19,H19<1),"Terlambat",IF(H19>0,"Berjalan","Belum Mulai"))) -> Selesai
A20: T3.2 | B20: Desain final (pita KTM) & halaman jadwal | C20: Frontend & Mobile | D20: T1.2 | E20: =IF($D20="",'Rencana Proyek'!$C$8,IFERROR(INDEX($G$7:$G$31,MATCH($D20,$A$7:$A$31,0))+1,'Rencana Proyek'!$C$8)) -> 46322 | F20: 1 | G20: =E20+F20-1 -> 46322 | H20: 1 | I20: =IF(H20>=1,"Selesai",IF(AND(TODAY()>G20,H20<1),"Terlambat",IF(H20>0,"Berjalan","Belum Mulai"))) -> Selesai
A21: T3.3 | B21: Aplikasi Android (Capacitor + NFC native) | C21: Frontend & Mobile | D21: T1.2 | E21: =IF($D21="",'Rencana Proyek'!$C$8,IFERROR(INDEX($G$7:$G$31,MATCH($D21,$A$7:$A$31,0))+1,'Rencana Proyek'!$C$8)) -> 46322 | F21: 1 | G21: =E21+F21-1 -> 46322 | H21: 1 | I21: =IF(H21>=1,"Selesai",IF(AND(TODAY()>G21,H21<1),"Terlambat",IF(H21>0,"Berjalan","Belum Mulai"))) -> Selesai
A22: F4 | B22: Fase 4 · Pengujian & Demo | E22: =MIN(E23:E26) -> 46322 | F22: =G22-E22+1 -> 10 | G22: =MAX(G23:G26) -> 46331 | H22: =IFERROR(SUMPRODUCT(F23:F26,H23:H26)/SUM(F23:F26),0) -> 0.1 | I22: =IF(H22>=1,"Selesai",IF(AND(TODAY()>G22,H22<1),"Terlambat",IF(H22>0,"Berjalan","Belum Mulai"))) -> Berjalan
A23: T4.1 | B23: Pengujian integrasi & unit test (Rust, Foundry) | C23: QA | D23: T1.2 | E23: =IF($D23="",'Rencana Proyek'!$C$8,IFERROR(INDEX($G$7:$G$31,MATCH($D23,$A$7:$A$31,0))+1,'Rencana Proyek'!$C$8)) -> 46322 | F23: 1 | G23: =E23+F23-1 -> 46322 | H23: 1 | I23: =IF(H23>=1,"Selesai",IF(AND(TODAY()>G23,H23<1),"Terlambat",IF(H23>0,"Berjalan","Belum Mulai"))) -> Selesai
A24: T4.2 | B24: Presentasi & demo ke dosen | C24: PM | D24: T4.1 | E24: =IF($D24="",'Rencana Proyek'!$C$8,IFERROR(INDEX($G$7:$G$31,MATCH($D24,$A$7:$A$31,0))+1,'Rencana Proyek'!$C$8)) -> 46323 | F24: 1 | G24: =E24+F24-1 -> 46323 | H24: 0 | I24: =IF(H24>=1,"Selesai",IF(AND(TODAY()>G24,H24<1),"Terlambat",IF(H24>0,"Berjalan","Belum Mulai"))) -> Belum Mulai
A25: T4.3 | B25: Uji pengguna dengan teman sekelas | C25: QA | D25: T4.2 | E25: =IF($D25="",'Rencana Proyek'!$C$8,IFERROR(INDEX($G$7:$G$31,MATCH($D25,$A$7:$A$31,0))+1,'Rencana Proyek'!$C$8)) -> 46324 | F25: 5 | G25: =E25+F25-1 -> 46328 | H25: 0 | I25: =IF(H25>=1,"Selesai",IF(AND(TODAY()>G25,H25<1),"Terlambat",IF(H25>0,"Berjalan","Belum Mulai"))) -> Belum Mulai
A26: T4.4 | B26: UAT bersama dosen | C26: PM | D26: T4.3 | E26: =IF($D26="",'Rencana Proyek'!$C$8,IFERROR(INDEX($G$7:$G$31,MATCH($D26,$A$7:$A$31,0))+1,'Rencana Proyek'!$C$8)) -> 46329 | F26: 3 | G26: =E26+F26-1 -> 46331 | H26: 0 | I26: =IF(H26>=1,"Selesai",IF(AND(TODAY()>G26,H26<1),"Terlambat",IF(H26>0,"Berjalan","Belum Mulai"))) -> Belum Mulai
A27: F5 | B27: Fase 5 · Rilis & Serah Terima | E27: =MIN(E28:E31) -> 46322 | F27: =G27-E27+1 -> 21 | G27: =MAX(G28:G31) -> 46342 | H27: =IFERROR(SUMPRODUCT(F28:F31,H28:H31)/SUM(F28:F31),0) -> 0.16666667 | I27: =IF(H27>=1,"Selesai",IF(AND(TODAY()>G27,H27<1),"Terlambat",IF(H27>0,"Berjalan","Belum Mulai"))) -> Berjalan
A28: T5.1 | B28: Deploy VPS, Cloudflare Tunnel & kontrak Sepolia | C28: Backend & Blockchain | D28: T1.2 | E28: =IF($D28="",'Rencana Proyek'!$C$8,IFERROR(INDEX($G$7:$G$31,MATCH($D28,$A$7:$A$31,0))+1,'Rencana Proyek'!$C$8)) -> 46322 | F28: 1 | G28: =E28+F28-1 -> 46322 | H28: 1 | I28: =IF(H28>=1,"Selesai",IF(AND(TODAY()>G28,H28<1),"Terlambat",IF(H28>0,"Berjalan","Belum Mulai"))) -> Selesai
A29: T5.2 | B29: Perbaikan bug hasil pengujian | C29: Backend & Blockchain | D29: T4.4 | E29: =IF($D29="",'Rencana Proyek'!$C$8,IFERROR(INDEX($G$7:$G$31,MATCH($D29,$A$7:$A$31,0))+1,'Rencana Proyek'!$C$8)) -> 46332 | F29: 5 | G29: =E29+F29-1 -> 46336 | H29: 0 | I29: =IF(H29>=1,"Selesai",IF(AND(TODAY()>G29,H29<1),"Terlambat",IF(H29>0,"Berjalan","Belum Mulai"))) -> Belum Mulai
A30: T5.3 | B30: Laporan MPI, dokumentasi & panduan pengguna | C30: PM | D30: T5.2 | E30: =IF($D30="",'Rencana Proyek'!$C$8,IFERROR(INDEX($G$7:$G$31,MATCH($D30,$A$7:$A$31,0))+1,'Rencana Proyek'!$C$8)) -> 46337 | F30: 4 | G30: =E30+F30-1 -> 46340 | H30: 0.25 | I30: =IF(H30>=1,"Selesai",IF(AND(TODAY()>G30,H30<1),"Terlambat",IF(H30>0,"Berjalan","Belum Mulai"))) -> Berjalan
A31: T5.4 | B31: Go-live & serah terima (APK final, repo publik) | C31: PM | D31: T5.3 | E31: =IF($D31="",'Rencana Proyek'!$C$8,IFERROR(INDEX($G$7:$G$31,MATCH($D31,$A$7:$A$31,0))+1,'Rencana Proyek'!$C$8)) -> 46341 | F31: 2 | G31: =E31+F31-1 -> 46342 | H31: 0 | I31: =IF(H31>=1,"Selesai",IF(AND(TODAY()>G31,H31<1),"Terlambat",IF(H31>0,"Berjalan","Belum Mulai"))) -> Belum Mulai
A33: Teks biru = bisa diubah. Mulai & Selesai dihitung otomatis dari hari pertama proyek (sheet Rencana Proyek, sel C8), pekerjaan sebelumnya, dan lama pengerjaan. Pekerjaan 100% memakai tanggal pengerjaan sebenarnya; sisanya rencana.
